2023-02-09 00:14:29,015 - instabot version: 0.117.0 (bot) - INFO - Instabot version: 0.117.0 Started
2023-02-09 00:14:29,018 - instabot version: 0.117.0 (bot) - DEBUG - Bot imported from C:\Users\Admin\AppData\Local\Programs\Python\Python38\lib\site-packages\instabot\bot\bot.py
2023-02-09 00:14:29,037 - instabot version: 0.117.0 (api_login) - INFO - Not yet logged in starting: PRE-LOGIN FLOW!
2023-02-09 00:14:51,555 - instabot version: 0.117.0 (api) - WARNING - HTTPSConnectionPool(host='i.instagram.com', port=443): Max retries exceeded with url: /api/v1/accounts/get_prefill_candidates/ (Caused by NewConnectionError('<urllib3.connection.HTTPSConnection object at 0x0000000004208CA0>: Failed to establish a new connection: [WinError 10060] A connection attempt failed because the connected party did not properly respond after a period of time, or established connection failed because connected host has failed to respond'))
2023-02-09 00:15:12,667 - instabot version: 0.117.0 (api) - WARNING - HTTPSConnectionPool(host='i.instagram.com', port=443): Max retries exceeded with url: /api/v1/qe/sync/ (Caused by NewConnectionError('<urllib3.connection.HTTPSConnection object at 0x000000000447A730>: Failed to establish a new connection: [WinError 10060] A connection attempt failed because the connected party did not properly respond after a period of time, or established connection failed because connected host has failed to respond'))
2023-02-09 00:15:14,619 - instabot version: 0.117.0 (api) - DEBUG - POST to endpoint: launcher/sync/ returned response: <Response [200]>
2023-02-09 00:15:15,223 - instabot version: 0.117.0 (api) - DEBUG - POST to endpoint: accounts/contact_point_prefill/ returned response: <Response [200]>
2023-02-09 00:15:17,939 - instabot version: 0.117.0 (api) - DEBUG - POST to endpoint: accounts/login/ returned response: <Response [200]>
2023-02-09 00:15:17,955 - instabot version: 0.117.0 (api) - INFO - Logged-in successfully as 'insta_mate_1'!
2023-02-09 00:15:17,956 - instabot version: 0.117.0 (api_login) - INFO - LOGIN FLOW! Just logged-in: True
2023-02-09 00:15:18,587 - instabot version: 0.117.0 (api) - DEBUG - POST to endpoint: qe/sync/ returned response: <Response [200]>
2023-02-09 00:15:19,275 - instabot version: 0.117.0 (api) - DEBUG - POST to endpoint: launcher/sync/ returned response: <Response [200]>
2023-02-09 00:15:19,783 - instabot version: 0.117.0 (api) - DEBUG - GET to endpoint: zr/token/result/?device_id=android-df6cbd7feeea9b64&token_hash=&custom_device_id=android-df6cbd7feeea9b64&fetch_reason=token_expired returned response: <Response [200]>
2023-02-09 00:15:20,260 - instabot version: 0.117.0 (api) - DEBUG - GET to endpoint: multiple_accounts/get_account_family/ returned response: <Response [200]>
2023-02-09 00:15:41,334 - instabot version: 0.117.0 (api) - WARNING - HTTPSConnectionPool(host='i.instagram.com', port=443): Max retries exceeded with url: /api/v1/qe/sync/ (Caused by NewConnectionError('<urllib3.connection.HTTPSConnection object at 0x000000000447A9A0>: Failed to establish a new connection: [WinError 10060] A connection attempt failed because the connected party did not properly respond after a period of time, or established connection failed because connected host has failed to respond'))
2023-02-09 00:16:02,466 - instabot version: 0.117.0 (api) - WARNING - HTTPSConnectionPool(host='i.instagram.com', port=443): Max retries exceeded with url: /api/v1/igtv/browse_feed/?prefetch=1 (Caused by NewConnectionError('<urllib3.connection.HTTPSConnection object at 0x00000000041E6DC0>: Failed to establish a new connection: [WinError 10060] A connection attempt failed because the connected party did not properly respond after a period of time, or established connection failed because connected host has failed to respond'))
2023-02-09 00:16:23,522 - instabot version: 0.117.0 (api) - WARNING - HTTPSConnectionPool(host='i.instagram.com', port=443): Max retries exceeded with url: /api/v1/creatives/ar_class/ (Caused by NewConnectionError('<urllib3.connection.HTTPSConnection object at 0x000000000447A6D0>: Failed to establish a new connection: [WinError 10060] A connection attempt failed because the connected party did not properly respond after a period of time, or established connection failed because connected host has failed to respond'))
2023-02-09 00:16:44,586 - instabot version: 0.117.0 (api) - WARNING - HTTPSConnectionPool(host='i.instagram.com', port=443): Max retries exceeded with url: /api/v1/feed/reels_tray/ (Caused by NewConnectionError('<urllib3.connection.HTTPSConnection object at 0x00000000042852B0>: Failed to establish a new connection: [WinError 10060] A connection attempt failed because the connected party did not properly respond after a period of time, or established connection failed because connected host has failed to respond'))
2023-02-09 00:17:07,360 - instabot version: 0.117.0 (api) - WARNING - HTTPSConnectionPool(host='i.instagram.com', port=443): Max retries exceeded with url: /api/v1/feed/timeline/ (Caused by NewConnectionError('<urllib3.connection.HTTPSConnection object at 0x0000000004295310>: Failed to establish a new connection: [WinError 10060] A connection attempt failed because the connected party did not properly respond after a period of time, or established connection failed because connected host has failed to respond'))
2023-02-09 00:17:28,432 - instabot version: 0.117.0 (api) - WARNING - HTTPSConnectionPool(host='i.instagram.com', port=443): Max retries exceeded with url: /api/v1/media/blocked/ (Caused by NewConnectionError('<urllib3.connection.HTTPSConnection object at 0x0000000004295790>: Failed to establish a new connection: [WinError 10060] A connection attempt failed because the connected party did not properly respond after a period of time, or established connection failed because connected host has failed to respond'))
2023-02-09 00:17:49,490 - instabot version: 0.117.0 (api) - WARNING - HTTPSConnectionPool(host='i.instagram.com', port=443): Max retries exceeded with url: /api/v1/news/inbox/ (Caused by NewConnectionError('<urllib3.connection.HTTPSConnection object at 0x0000000004295C10>: Failed to establish a new connection: [WinError 10060] A connection attempt failed because the connected party did not properly respond after a period of time, or established connection failed because connected host has failed to respond'))
2023-02-09 00:18:10,627 - instabot version: 0.117.0 (api) - WARNING - HTTPSConnectionPool(host='i.instagram.com', port=443): Max retries exceeded with url: /api/v1/loom/fetch_config/ (Caused by NewConnectionError('<urllib3.connection.HTTPSConnection object at 0x00000000042954F0>: Failed to establish a new connection: [WinError 10060] A connection attempt failed because the connected party did not properly respond after a period of time, or established connection failed because connected host has failed to respond'))
2023-02-09 00:18:31,715 - instabot version: 0.117.0 (api) - WARNING - HTTPSConnectionPool(host='i.instagram.com', port=443): Max retries exceeded with url: /api/v1/scores/bootstrap/users/?surfaces=%5B%22autocomplete_user_list%22,%22coefficient_besties_list_ranking%22,%22coefficient_rank_recipient_user_suggestion%22,%22coefficient_ios_section_test_bootstrap_ranking%22,%22coefficient_direct_recipients_ranking_variant_2%22%5D (Caused by NewConnectionError('<urllib3.connection.HTTPSConnection object at 0x0000000004295700>: Failed to establish a new connection: [WinError 10060] A connection attempt failed because the connected party did not properly respond after a period of time, or established connection failed because connected host has failed to respond'))
2023-02-09 00:18:52,833 - instabot version: 0.117.0 (api) - WARNING - HTTPSConnectionPool(host='i.instagram.com', port=443): Max retries exceeded with url: /api/v1/business/eligibility/get_monetization_products_eligibility_data/?product_types=branded_content (Caused by NewConnectionError('<urllib3.connection.HTTPSConnection object at 0x00000000042950A0>: Failed to establish a new connection: [WinError 10060] A connection attempt failed because the connected party did not properly respond after a period of time, or established connection failed because connected host has failed to respond'))
2023-02-09 00:19:13,935 - instabot version: 0.117.0 (api) - WARNING - HTTPSConnectionPool(host='i.instagram.com', port=443): Max retries exceeded with url: /api/v1/business/branded_content/should_require_professional_account/ (Caused by NewConnectionError('<urllib3.connection.HTTPSConnection object at 0x0000000004285430>: Failed to establish a new connection: [WinError 10060] A connection attempt failed because the connected party did not properly respond after a period of time, or established connection failed because connected host has failed to respond'))
2023-02-09 00:19:34,964 - instabot version: 0.117.0 (api) - WARNING - HTTPSConnectionPool(host='i.instagram.com', port=443): Max retries exceeded with url: /api/v1/linked_accounts/get_linkage_status/ (Caused by NewConnectionError('<urllib3.connection.HTTPSConnection object at 0x000000000447AD00>: Failed to establish a new connection: [WinError 10060] A connection attempt failed because the connected party did not properly respond after a period of time, or established connection failed because connected host has failed to respond'))
2023-02-09 00:19:56,107 - instabot version: 0.117.0 (api) - WARNING - HTTPSConnectionPool(host='i.instagram.com', port=443): Max retries exceeded with url: /api/v1/locations/request_country/ (Caused by NewConnectionError('<urllib3.connection.HTTPSConnection object at 0x000000000447A9A0>: Failed to establish a new connection: [WinError 10060] A connection attempt failed because the connected party did not properly respond after a period of time, or established connection failed because connected host has failed to respond'))
2023-02-09 00:20:17,185 - instabot version: 0.117.0 (api) - WARNING - HTTPSConnectionPool(host='i.instagram.com', port=443): Max retries exceeded with url: /api/v1/qp/get_cooldowns/?signed_body=signed_body=4b9c516a5410a3bc128e09c6104a7f042146b9c2023870560c63a43a7f66781c.4&ig_sig_key_version=4&ig_sig_key_version=4 (Caused by NewConnectionError('<urllib3.connection.HTTPSConnection object at 0x00000000041E6730>: Failed to establish a new connection: [WinError 10060] A connection attempt failed because the connected party did not properly respond after a period of time, or established connection failed because connected host has failed to respond'))
2023-02-09 00:20:38,277 - instabot version: 0.117.0 (api) - WARNING - HTTPSConnectionPool(host='i.instagram.com', port=443): Max retries exceeded with url: /api/v1/users/arlink_download_info/?version_override=2.2.1 (Caused by NewConnectionError('<urllib3.connection.HTTPSConnection object at 0x00000000042A5040>: Failed to establish a new connection: [WinError 10060] A connection attempt failed because the connected party did not properly respond after a period of time, or established connection failed because connected host has failed to respond'))
2023-02-09 00:21:00,221 - instabot version: 0.117.0 (api) - WARNING - HTTPSConnectionPool(host='i.instagram.com', port=443): Max retries exceeded with url: /api/v1/users/57720583483/info/ (Caused by NewConnectionError('<urllib3.connection.HTTPSConnection object at 0x00000000042A5610>: Failed to establish a new connection: [WinError 10060] A connection attempt failed because the connected party did not properly respond after a period of time, or established connection failed because connected host has failed to respond'))
2023-02-09 00:21:00,941 - instabot version: 0.117.0 (api) - DEBUG - GET to endpoint: direct_v2/get_presence/ returned response: <Response [200]>
2023-02-09 00:21:04,635 - instabot version: 0.117.0 (api) - DEBUG - GET to endpoint: direct_v2/inbox/?visual_message_return_type=unseen&thread_message_limit=10&persistentBadging=true&limit=20 returned response: <Response [200]>
2023-02-09 00:21:25,713 - instabot version: 0.117.0 (api) - WARNING - HTTPSConnectionPool(host='i.instagram.com', port=443): Max retries exceeded with url: /api/v1/direct_v2/inbox/?visual_message_return_type=unseen&persistentBadging=true&limit=0 (Caused by NewConnectionError('<urllib3.connection.HTTPSConnection object at 0x00000000041E6880>: Failed to establish a new connection: [WinError 10060] A connection attempt failed because the connected party did not properly respond after a period of time, or established connection failed because connected host has failed to respond'))
2023-02-09 00:21:46,900 - instabot version: 0.117.0 (api) - WARNING - HTTPSConnectionPool(host='i.instagram.com', port=443): Max retries exceeded with url: /api/v1/discover/topical_explore/?is_prefetch=true&omit_cover_media=true&use_sectional_payload=true&timezone_offset=0&session_id=5e212f7e-992d-45d7-80b4-6fe3aa9845fd&include_fixed_destinations=true (Caused by NewConnectionError('<urllib3.connection.HTTPSConnection object at 0x000000000447AD60>: Failed to establish a new connection: [WinError 10060] A connection attempt failed because the connected party did not properly respond after a period of time, or established connection failed because connected host has failed to respond'))
2023-02-09 00:22:08,016 - instabot version: 0.117.0 (api) - WARNING - HTTPSConnectionPool(host='i.instagram.com', port=443): Max retries exceeded with url: /api/v1/notifications/badge/ (Caused by NewConnectionError('<urllib3.connection.HTTPSConnection object at 0x000000000447A910>: Failed to establish a new connection: [WinError 10060] A connection attempt failed because the connected party did not properly respond after a period of time, or established connection failed because connected host has failed to respond'))
2023-02-09 00:22:29,180 - instabot version: 0.117.0 (api) - WARNING - HTTPSConnectionPool(host='i.instagram.com', port=443): Max retries exceeded with url: /api/v1/qp/batch_fetch/ (Caused by NewConnectionError('<urllib3.connection.HTTPSConnection object at 0x00000000042850D0>: Failed to establish a new connection: [WinError 10060] A connection attempt failed because the connected party did not properly respond after a period of time, or established connection failed because connected host has failed to respond'))
2023-02-09 00:22:29,200 - instabot version: 0.117.0 (bot_checkpoint) - DEBUG - Loading Checkpoint file from: C:\Users\Admin\Desktop\InstaMate/config/insta_mate_1.checkpoint
